Workbook

Sheet 합계
A1: no | B1: 학교명 | C1: 계약금액 | D1: 하청 | E1: 배송비 | F1: 합계 | G1: 수익 | H1: 수익률
A2: 1 | B2: ='1'!A33 -> 온천초 | C2: ='1'!B32 -> 10525500 | D2: ='1'!K31 -> 7261100 | E2: ='1'!K32 -> 275000 | F2: ='1'!K33 -> 7536100 | G2: =C2-F2 -> 2989400 | H2: =G2/C2 -> 0.28401501
A3: 2 | B3: ='2'!A33 -> 구화학교 | C3: ='2'!B32 -> 3139840 | D3: ='2'!K31 -> 2138500 | E3: ='2'!K32 -> 325000 | F3: ='2'!K33 -> 2463500 | G3: =C3-F3 -> 676340 | H3: =G3/C3 -> 0.21540588
A4: 3 | B4: ='3'!A33 -> 백양고 | C4: ='3'!B32 -> 4778780 | D4: ='3'!K31 -> 2936700 | E4: ='3'!K32 -> 275000 | F4: ='3'!K33 -> 3211700 | G4: =C4-F4 -> 1567080 | H4: =G4/C4 -> 0.3279247
A5: 4 | B5: ='4'!A33 -> 신정초 | C5: ='4'!B32 -> 8358600 | D5: ='4'!K31 -> 5345800 | E5: ='4'!K32 -> 200000 | F5: ='4'!K33 -> 5545800 | G5: =C5-F5 -> 2812800 | H5: =G5/C5 -> 0.33651568
A6: 5
A7: 6
A8: 7
A9: 8
A10: 9
A11: 10
A12: 11
A13: 12
A14: 13
A15: 14
A16: 15
A17: 16
... A21: 20
A22: 합계 | B22: ='1'!A53 -> 0 | C22: =SUM(C2:C21) -> 26802720 | D22: =SUM(D2:D21) -> 17682100 | E22: =SUM(E2:E21) -> 1075000 | F22: =SUM(F2:F21) -> 18757100 | G22: =SUM(G2:G21) -> 8045620 | H22: =H2+H3+H4+H5 -> 1.1638613 | I22: =H22/4 -> 0.29096532
F23: =F22-F3 -> 16293600

Sheet 1
A1: 품목 | B1: 입찰수량 | C1: 입찰단가 | D1: 입찰금액 | E1: 입찰-차액 | F1: 차액/수량 | H1: 품목 | I1: 수량 | J1: 태성단가 | K1: 합계
A2: 돼지고기(갈비)/찜용 | B2: 110 | C2: 12000 | D2: =B2*C2 -> 1320000 | E2: =D2+$E$32 -> 1320000 | F2: =E2/B2 -> 12000 | H2: =A2 -> 돼지고기(갈비)/찜용 | I2: =B2 -> 110 | J2: 8800 | K2: =I2*J2 -> 968000
A3: 돼지고기(갈비)/탕용 | B3: 40 | C3: 12000 | D3: =B3*C3 -> 480000 | E3: =D3+$E$32 -> 480000 | F3: =E3/B3 -> 12000 | H3: =A3 -> 돼지고기(갈비)/탕용 | I3: =B3 -> 40 | J3: 8800 | K3: =I3*J3 -> 352000
A4: 돼지고기(뒷다리, 후지)/다진것 | B4: 40 | C4: 12000 | D4: =B4*C4 -> 480000 | E4: =D4+$E$32 -> 480000 | F4: =E4/B4 -> 12000 | H4: =A4 -> 돼지고기(뒷다리, 후지)/다진것 | I4: =B4 -> 40 | J4: 7300 | K4: =I4*J4 -> 292000
A5: 돼지고기(뒷다리, 후지)/불고기용 | B5: 20 | C5: 12025 | D5: =B5*C5 -> 240500 | E5: =D5+$E$32 -> 240500 | F5: =E5/B5 -> 12025 | H5: =A5 -> 돼지고기(뒷다리, 후지)/불고기용 | I5: =B5 -> 20 | J5: 7300 | K5: =I5*J5 -> 146000
A6: 돼지고기(뒷다리, 후지)/슬라이스 | B6: 32 | C6: 12000 | D6: =B6*C6 -> 384000 | E6: =D6+$E$32 -> 384000 | F6: =E6/B6 -> 12000 | H6: =A6 -> 돼지고기(뒷다리, 후지)/슬라이스 | I6: =B6 -> 32 | J6: 7300 | K6: =I6*J6 -> 233600
A7: 돼지고기(뒷다리, 후지)/채썬것(세절) | B7: 45 | C7: 12000 | D7: =B7*C7 -> 540000 | E7: =D7+$E$32 -> 540000 | F7: =E7/B7 -> 12000 | H7: =A7 -> 돼지고기(뒷다리, 후지)/채썬것(세절) | I7: =B7 -> 45 | J7: 7300 | K7: =I7*J7 -> 328500
A8: 돼지고기(뒷다리, 후지)/카레용 | B8: 25 | C8: 12000 | D8: =B8*C8 -> 300000 | E8: =D8+$E$32 -> 300000 | F8: =E8/B8 -> 12000 | H8: =A8 -> 돼지고기(뒷다리, 후지)/카레용 | I8: =B8 -> 25 | J8: 7300 | K8: =I8*J8 -> 182500
A9: 돼지고기(앞다리, 전지)/불고기용 | B9: 207 | C9: 11000 | D9: =B9*C9 -> 2277000 | E9: =D9+$E$32 -> 2277000 | F9: =E9/B9 -> 11000 | H9: =A9 -> 돼지고기(앞다리, 전지)/불고기용 | I9: =B9 -> 207 | J9: 8500 | K9: =I9*J9 -> 1759500
A10: 돼지고기(앞다리, 전지)/편육용 | B10: 88 | C10: 11000 | D10: =B10*C10 -> 968000 | E10: =D10+$E$32 -> 968000 | F10: =E10/B10 -> 11000 | H10: =A10 -> 돼지고기(앞다리, 전지)/편육용 | I10: =B10 -> 88 | J10: 8500 | K10: =I10*J10 -> 748000
A11: 돼지등뼈 | B11: 25 | C11: 9000 | D11: =B11*C11 -> 225000 | E11: =D11+$E$32 -> 225000 | F11: =E11/B11 -> 9000 | H11: =A11 -> 돼지등뼈 | I11: =B11 -> 25 | J11: 3800 | K11: =I11*J11 -> 95000
A12: 한우(양지)/국용 | B12: 53 | C12: 43000 | D12: =B12*C12 -> 2279000 | E12: =D12+$E$32 -> 2279000 | F12: =E12/B12 -> 43000 | H12: =A12 -> 한우(양지)/국용 | I12: =B12 -> 53 | J12: 28000 | K12: =I12*J12 -> 1484000
A13: 한우(양지)/다진것 | B13: 8 | C13: 43000 | D13: =B13*C13 -> 344000 | E13: =D13+$E$32 -> 344000 | F13: =E13/B13 -> 43000 | H13: =A13 -> 한우(양지)/다진것 | I13: =B13 -> 8 | J13: 28000 | K13: =I13*J13 -> 224000
A14: 한우(우둔)/채썬것(세절) | B14: 16 | C14: 43000 | D14: =B14*C14 -> 688000 | E14: =D14+$E$32 -> 688000 | F14: =E14/B14 -> 43000 | H14: =A14 -> 한우(우둔)/채썬것(세절) | I14: =B14 -> 16 | J14: 28000 | K14: =I14*J14 -> 448000
D15: =B15*C15 -> 0 | F15: =E15/B15 -> #DIV/0! | H15: =A15 -> 0 | I15: =B15 -> 0 | K15: =I15*J15 -> 0
D16: =B16*C16 -> 0 | F16: =E16/B16 -> #DIV/0! | H16: =A16 -> 0 | I16: =B16 -> 0 | K16: =I16*J16 -> 0
D17: =B17*C17 -> 0 | F17: =E17/B17 -> #DIV/0! | H17: =A17 -> 0 | I17: =B17 -> 0 | K17: =I17*J17 -> 0
D18: =B18*C18 -> 0 | F18: =E18/B18 -> #DIV/0! | H18: =A18 -> 0 | I18: =B18 -> 0 | K18: =I18*J18 -> 0
D19: =B19*C19 -> 0 | F19: =E19/B19 -> #DIV/0! | H19: =A19 -> 0 | I19: =B19 -> 0 | K19: =I19*J19 -> 0
D20: =B20*C20 -> 0 | F20: =E20/B20 -> #DIV/0! | H20: =A20 -> 0 | I20: =B20 -> 0 | K20: =I20*J20 -> 0
H21: =A21 -> 0 | I21: =B21 -> 0 | K21: =I21*J21 -> 0
H22: =A22 -> 0 | I22: =B22 -> 0 | K22: =I22*J22 -> 0
H23: =A23 -> 0 | I23: =B23 -> 0 | K23: =I23*J23 -> 0
H24: =A24 -> 0 | I24: =B24 -> 0 | K24: =I24*J24 -> 0
H25: =A25 -> 0 | I25: =B25 -> 0 | K25: =I25*J25 -> 0
H26: =A26 -> 0 | I26: =B26 -> 0 | K26: =I26*J26 -> 0
H27: =A27 -> 0 | I27: =B27 -> 0 | K27: =I27*J27 -> 0
H28: =A28 -> 0 | I28: =B28 -> 0 | K28: =I28*J28 -> 0
H29: =A29 -> 0 | I29: =B29 -> 0 | K29: =I29*J29 -> 0
H30: =A30 -> 0 | I30: =B30 -> 0 | K30: =I30*J30 -> 0
H31: =B32 -> 10525500 | K31: =SUM(K2:K30) -> 7261100
A32: 계약금액 | B32: 10525500 | D32: =SUM(D2:D31) -> 10525500 | E32: =B32-D32 -> 0 | I32: 11 | J32: 25000 | K32: =I32*J32 -> 275000
A33: 온천초 | B33: =B2 -> 110 | C33: =$E$32/B33 -> 0 | E33: 차액 | K33: =K31+K32 -> 7536100
B34: =B3 -> 40 | C34: =$E$32/B34 -> 0 | K34: =H31-K33 -> 2989400
B35: =B4 -> 40 | C35: =$E$32/B35 -> 0 | K35: =K34/H31 -> 0.28401501
B36: =B5 -> 20 | C36: =$E$32/B36 -> 0
B37: =B6 -> 32
B38: =B7 -> 45 | G38: 3110800
B39: =B8 -> 25
B40: =B9 -> 207
...

Sheet 2
A1: 품목 | B1: 입찰수량 | C1: 입찰단가 | D1: 입찰금액 | E1: 입찰-차액 | F1: 차액/수량 | H1: 품목 | I1: 수량 | J1: 태성단가 | K1: 합계
A2: 돼지고기(목살)/깍둑썰기 | B2: 17 | C2: 18000 | D2: =B2*C2 -> 306000 | E2: =D2+$E$32 -> 521000 | F2: =E2/B2 -> 30647.059 | H2: =A2 -> 돼지고기(목살)/깍둑썰기 | I2: =B2 -> 17 | J2: 14000 | K2: =I2*J2 -> 238000
A3: 돼지고기(목살)/수육용 | B3: 16 | C3: 18000 | D3: =B3*C3 -> 288000 | E3: =D3+$E$32 -> 503000 | F3: =E3/B3 -> 31437.5 | H3: =A3 -> 돼지고기(목살)/수육용 | I3: =B3 -> 16 | J3: 14000 | K3: =I3*J3 -> 224000
A4: 돼지고기(앞다리, 전지)/불고기용 | B4: 17 | C4: 15000 | D4: =B4*C4 -> 255000 | E4: =D4+$E$32 -> 470000 | F4: =E4/B4 -> 27647.059 | H4: =A4 -> 돼지고기(앞다리, 전지)/불고기용 | I4: =B4 -> 17 | J4: 8500 | K4: =I4*J4 -> 144500
A5: 한우(갈비)/탕용 | B5: 10 | C5: 39884 | D5: =B5*C5 -> 398840 | E5: =D5+$E$32 -> 613840 | F5: =E5/B5 -> 61384 | H5: =A5 -> 한우(갈비)/탕용 | I5: =B5 -> 10 | J5: 30000 | K5: =I5*J5 -> 300000
A6: 한우(사태) | B6: 16 | C6: 43000 | D6: =B6*C6 -> 688000 | E6: =D6+$E$32 -> 903000 | F6: =E6/B6 -> 56437.5 | H6: =A6 -> 한우(사태) | I6: =B6 -> 16 | J6: 28000 | K6: =I6*J6 -> 448000
A7: 한우(설도)/국용 | B7: 1 | C7: 43000 | D7: =B7*C7 -> 43000 | E7: =D7+$E$32 -> 258000 | F7: =E7/B7 -> 258000 | H7: =A7 -> 한우(설도)/국용 | I7: =B7 -> 1 | J7: 28000 | K7: =I7*J7 -> 28000
A8: 한우(설도)/스테이크용 | B8: 1 | C8: 43000 | D8: =B8*C8 -> 43000 | E8: =D8+$E$32 -> 258000 | F8: =E8/B8 -> 258000 | H8: =A8 -> 한우(설도)/스테이크용 | I8: =B8 -> 1 | J8: 28000 | K8: =I8*J8 -> 28000
A9: 한우(설도)/채썬것(세절) | B9: 3 | C9: 43000 | D9: =B9*C9 -> 129000 | E9: =D9+$E$32 -> 344000 | F9: =E9/B9 -> 114666.67 | H9: =A9 -> 한우(설도)/채썬것(세절) | I9: =B9 -> 3 | J9: 28000 | K9: =I9*J9 -> 84000
A10: 한우(양지)/국용 | B10: 9 | C10: 43000 | D10: =B10*C10 -> 387000 | E10: =D10+$E$32 -> 602000 | F10: =E10/B10 -> 66888.889 | H10: =A10 -> 한우(양지)/국용 | I10: =B10 -> 9 | J10: 28000 | K10: =I10*J10 -> 252000
A11: 한우(우둔)/다진것 | B11: 9 | C11: 43000 | D11: =B11*C11 -> 387000 | E11: =D11+$E$32 -> 602000 | F11: =E11/B11 -> 66888.889 | H11: =A11 -> 한우(우둔)/다진것 | I11: =B11 -> 9 | J11: 28000 | K11: =I11*J11 -> 252000
A12: 한우(우둔)/채썬것(세절) | B12: 5 | C12: 43000 | D12: 2512_ | E12: =D12+$E$32 -> #VALUE! | F12: =E12/B12 -> #VALUE! | H12: =A12 -> 한우(우둔)/채썬것(세절) | I12: =B12 -> 5 | J12: 28000 | K12: =I12*J12 -> 140000
D13: =B13*C13 -> 0 | E13: =D13+$E$32 -> 215000 | F13: =E13/B13 -> #DIV/0! | H13: =A13 -> 0 | I13: =B13 -> 0 | K13: =I13*J13 -> 0
D14: =B14*C14 -> 0 | E14: =D14+$E$32 -> 215000 | F14: =E14/B14 -> #DIV/0! | H14: =A14 -> 0 | I14: =B14 -> 0 | K14: =I14*J14 -> 0
D15: =B15*C15 -> 0 | E15: =D15+$E$32 -> 215000 | F15: =E15/B15 -> #DIV/0! | H15: =A15 -> 0 | I15: =B15 -> 0 | K15: =I15*J15 -> 0
D16: =B16*C16 -> 0 | E16: =D16+$E$32 -> 215000 | F16: =E16/B16 -> #DIV/0! | H16: =A16 -> 0 | I16: =B16 -> 0 | K16: =I16*J16 -> 0
D17: =B17*C17 -> 0 | E17: =D17+$E$32 -> 215000 | F17: =E17/B17 -> #DIV/0! | H17: =A17 -> 0 | I17: =B17 -> 0 | K17: =I17*J17 -> 0
D18: =B18*C18 -> 0 | E18: =D18+$E$32 -> 215000 | F18: =E18/B18 -> #DIV/0! | H18: =A18 -> 0 | I18: =B18 -> 0 | K18: =I18*J18 -> 0
D19: =B19*C19 -> 0 | E19: =D19+$E$32 -> 215000 | F19: =E19/B19 -> #DIV/0! | H19: =A19 -> 0 | I19: =B19 -> 0 | K19: =I19*J19 -> 0
D20: =B20*C20 -> 0 | E20: =D20+$E$32 -> 215000 | F20: =E20/B20 -> #DIV/0! | H20: =A20 -> 0 | I20: =B20 -> 0 | K20: =I20*J20 -> 0
H21: =A21 -> 0 | I21: =B21 -> 0 | K21: =I21*J21 -> 0
H22: =A22 -> 0 | I22: =B22 -> 0 | K22: =I22*J22 -> 0
H23: =A23 -> 0 | I23: =B23 -> 0 | K23: =I23*J23 -> 0
H24: =A24 -> 0 | I24: =B24 -> 0 | K24: =I24*J24 -> 0
H25: =A25 -> 0 | I25: =B25 -> 0 | K25: =I25*J25 -> 0
H26: =A26 -> 0 | I26: =B26 -> 0 | K26: =I26*J26 -> 0
H27: =A27 -> 0 | I27: =B27 -> 0 | K27: =I27*J27 -> 0
H28: =A28 -> 0 | I28: =B28 -> 0 | K28: =I28*J28 -> 0
H29: =A29 -> 0 | I29: =B29 -> 0 | K29: =I29*J29 -> 0
H30: =A30 -> 0 | I30: =B30 -> 0 | K30: =I30*J30 -> 0
H31: =B32 -> 3139840 | K31: =SUM(K2:K30) -> 2138500
A32: 계약금액 | B32: 3139840 | D32: =SUM(D2:D31) -> 2924840 | E32: =B32-D32 -> 215000 | I32: 13 | J32: 25000 | K32: =I32*J32 -> 325000
A33: 구화학교 | B33: =B2 -> 17 | C33: =$E$32/B33 -> 12647.059 | E33: 차액 | K33: =K31+K32 -> 2463500
B34: =B3 -> 16 | C34: =$E$32/B34 -> 13437.5 | K34: =H31-K33 -> 676340
B35: =B4 -> 17 | C35: =$E$32/B35 -> 12647.059 | K35: =K34/H31 -> 0.21540588
B36: =B5 -> 10 | C36: =$E$32/B36 -> 21500
B37: =B6 -> 16
B38: =B7 -> 1 | G38: 3110800
B39: =B8 -> 1
B40: =B9 -> 3
...

Sheet 3
A1: 품목 | B1: 입찰수량 | C1: 입찰단가 | D1: 입찰금액 | E1: 입찰-차액 | F1: 차액/수량 | H1: 품목 | I1: 수량 | J1: 태성단가 | K1: 합계
D2: =B2*C2 -> 0 | E2: =D2+$E$32 -> 0 | F2: =E2/B2 -> #DIV/0! | H2: =A2 -> 0 | I2: =B2 -> 0 | K2: =I2*J2 -> 0
A3: 돼지고기(갈비) | B3: 5 | C3: 15000 | D3: =B3*C3 -> 75000 | E3: =D3+$E$32 -> 75000 | F3: =E3/B3 -> 15000 | H3: =A3 -> 돼지고기(갈비) | I3: =B3 -> 5 | J3: 8800 | K3: =I3*J3 -> 44000
A4: 돼지고기(뒷다리, 후지) | B4: 7 | C4: 12000 | D4: =B4*C4 -> 84000 | E4: =D4+$E$32 -> 84000 | F4: =E4/B4 -> 12000 | H4: =A4 -> 돼지고기(뒷다리, 후지) | I4: =B4 -> 7 | J4: 7300 | K4: =I4*J4 -> 51100
A5: 돼지고기(뒷다리, 후지)/채썬것(세절) | B5: 5 | C5: 12000 | D5: =B5*C5 -> 60000 | E5: =D5+$E$32 -> 60000 | F5: =E5/B5 -> 12000 | H5: =A5 -> 돼지고기(뒷다리, 후지)/채썬것(세절) | I5: =B5 -> 5 | J5: 7300 | K5: =I5*J5 -> 36500
A6: 돼지고기(뒷다리, 후지)/카레용 | B6: 7 | C6: 12000 | D6: =B6*C6 -> 84000 | E6: =D6+$E$32 -> 84000 | F6: =E6/B6 -> 12000 | H6: =A6 -> 돼지고기(뒷다리, 후지)/카레용 | I6: =B6 -> 7 | J6: 7300 | K6: =I6*J6 -> 51100
A7: 돼지고기(앞다리, 전지) | B7: 201 | C7: 15000 | D7: =B7*C7 -> 3015000 | E7: =D7+$E$32 -> 3015000 | F7: =E7/B7 -> 15000 | H7: =A7 -> 돼지고기(앞다리, 전지) | I7: =B7 -> 201 | J7: 8500 | K7: =I7*J7 -> 1708500
A8: 돼지단족 | B8: 10 | C8: 8000 | D8: =B8*C8 -> 80000 | E8: =D8+$E$32 -> 80000 | F8: =E8/B8 -> 8000 | H8: =A8 -> 돼지단족 | I8: =B8 -> 10 | J8: 5500 | K8: =I8*J8 -> 55000
A9: 돼지등뼈 | B9: 20 | C9: 3939 | D9: =B9*C9 -> 78780 | E9: =D9+$E$32 -> 78780 | F9: =E9/B9 -> 3939 | H9: =A9 -> 돼지등뼈 | I9: =B9 -> 20 | J9: 3800 | K9: =I9*J9 -> 76000
A10: 한우(사태)/국산 | B10: 3 | C10: 42000 | D10: =B10*C10 -> 126000 | E10: =D10+$E$32 -> 126000 | F10: =E10/B10 -> 42000 | H10: =A10 -> 한우(사태)/국산 | I10: =B10 -> 3 | J10: 29500 | K10: =I10*J10 -> 88500
A11: 한우(양지) | B11: 25 | C11: 42000 | D11: =B11*C11 -> 1050000 | E11: =D11+$E$32 -> 1050000 | F11: =E11/B11 -> 42000 | H11: =A11 -> 한우(양지) | I11: =B11 -> 25 | J11: 29500 | K11: =I11*J11 -> 737500
A12: 한우(우둔) | B12: 3 | C12: 42000 | D12: =B12*C12 -> 126000 | E12: =D12+$E$32 -> 126000 | F12: =E12/B12 -> 42000 | H12: =A12 -> 한우(우둔) | I12: =B12 -> 3 | J12: 29500 | K12: =I12*J12 -> 88500
D13: =B13*C13 -> 0 | E13: =D13+$E$32 -> 0 | F13: =E13/B13 -> #DIV/0! | H13: =A13 -> 0 | I13: =B13 -> 0 | K13: =I13*J13 -> 0
D14: =B14*C14 -> 0 | E14: =D14+$E$32 -> 0 | F14: =E14/B14 -> #DIV/0! | H14: =A14 -> 0 | I14: =B14 -> 0 | K14: =I14*J14 -> 0
D15: =B15*C15 -> 0 | E15: =D15+$E$32 -> 0 | F15: =E15/B15 -> #DIV/0! | H15: =A15 -> 0 | I15: =B15 -> 0 | K15: =I15*J15 -> 0
D16: =B16*C16 -> 0 | E16: =D16+$E$32 -> 0 | F16: =E16/B16 -> #DIV/0! | H16: =A16 -> 0 | I16: =B16 -> 0 | K16: =I16*J16 -> 0
D17: =B17*C17 -> 0 | E17: =D17+$E$32 -> 0 | F17: =E17/B17 -> #DIV/0! | H17: =A17 -> 0 | I17: =B17 -> 0 | K17: =I17*J17 -> 0
D18: =B18*C18 -> 0 | E18: =D18+$E$32 -> 0 | F18: =E18/B18 -> #DIV/0! | H18: =A18 -> 0 | I18: =B18 -> 0 | K18: =I18*J18 -> 0
D19: =B19*C19 -> 0 | E19: =D19+$E$32 -> 0 | F19: =E19/B19 -> #DIV/0! | H19: =A19 -> 0 | I19: =B19 -> 0 | K19: =I19*J19 -> 0
D20: =B20*C20 -> 0 | E20: =D20+$E$32 -> 0 | F20: =E20/B20 -> #DIV/0! | H20: =A20 -> 0 | I20: =B20 -> 0 | K20: =I20*J20 -> 0
H21: =A21 -> 0 | I21: =B21 -> 0 | K21: =I21*J21 -> 0
H22: =A22 -> 0 | I22: =B22 -> 0 | K22: =I22*J22 -> 0
H23: =A23 -> 0 | I23: =B23 -> 0 | K23: =I23*J23 -> 0
H24: =A24 -> 0 | I24: =B24 -> 0 | K24: =I24*J24 -> 0
H25: =A25 -> 0 | I25: =B25 -> 0 | K25: =I25*J25 -> 0
H26: =A26 -> 0 | I26: =B26 -> 0 | K26: =I26*J26 -> 0
H27: =A27 -> 0 | I27: =B27 -> 0 | K27: =I27*J27 -> 0
H28: =A28 -> 0 | I28: =B28 -> 0 | K28: =I28*J28 -> 0
H29: =A29 -> 0 | I29: =B29 -> 0 | K29: =I29*J29 -> 0
H30: =A30 -> 0 | I30: =B30 -> 0 | K30: =I30*J30 -> 0
H31: =B32 -> 4778780 | K31: =SUM(K2:K30) -> 2936700
A32: 계약금액 | B32: 4778780 | D32: =SUM(D2:D31) -> 4778780 | E32: =B32-D32 -> 0 | I32: 11 | J32: 25000 | K32: =I32*J32 -> 275000
A33: 백양고 | B33: =B2 -> 0 | C33: =$E$32/B33 -> #DIV/0! | E33: 차액 | K33: =K31+K32 -> 3211700
B34: =B3 -> 5 | C34: =$E$32/B34 -> 0 | K34: =H31-K33 -> 1567080
B35: =B4 -> 7 | C35: =$E$32/B35 -> 0 | K35: =K34/H31 -> 0.3279247
B36: =B5 -> 5 | C36: =$E$32/B36 -> 0
B37: =B6 -> 7
B38: =B7 -> 201 | G38: 3110800
B39: =B8 -> 10
B40: =B9 -> 20
...

Sheet 4
A1: 품목 | B1: 입찰수량 | C1: 입찰단가 | D1: 입찰금액 | E1: 입찰-차액 | F1: 차액/수량 | H1: 품목 | I1: 수량 | J1: 태성단가 | K1: 합계
A2: 돼지고기(갈비)/찜용 | B2: 15 | C2: 18000 | D2: =B2*C2 -> 270000 | E2: =D2+$E$32 -> 270000 | F2: =E2/B2 -> 18000 | H2: =A2 -> 돼지고기(갈비)/찜용 | I2: 15 | J2: 8800 | K2: =I2*J2 -> 132000
A3: 돼지고기(뒷다리, 후지)/카레용 | B3: 0 | C3: 12000 | D3: =B3*C3 -> 0 | E3: =D3+$E$32 -> 0 | F3: =E3/B3 -> #DIV/0! | H3: =A3 -> 돼지고기(뒷다리, 후지)/카레용 | I3: 0 | J3: 7300 | K3: =I3*J3 -> 0
A4: 돼지고기(목살)/수육용 | B4: 58 | C4: 21000 | D4: =B4*C4 -> 1218000 | E4: =D4+$E$32 -> 1218000 | F4: =E4/B4 -> 21000 | H4: =A4 -> 돼지고기(목살)/수육용 | I4: 58 | J4: 14000 | K4: =I4*J4 -> 812000
A5: 돼지고기(목살)/스테이크용 | B5: 70 | C5: 21000 | D5: =B5*C5 -> 1470000 | E5: =D5+$E$32 -> 1470000 | F5: =E5/B5 -> 21000 | H5: =A5 -> 돼지고기(목살)/스테이크용 | I5: 70 | J5: 14000 | K5: =I5*J5 -> 980000
A6: 돼지고기(삼겹살)/불고기용 | B6: 0 | C6: =J6*2 -> 35000 | D6: =B6*C6 -> 0 | E6: =D6+$E$32 -> 0 | F6: =E6/B6 -> #DIV/0! | H6: =A6 -> 돼지고기(삼겹살)/불고기용 | I6: 0 | J6: 17500 | K6: =I6*J6 -> 0
A7: 돼지고기(앞다리, 전지)/불고기용 | B7: 130 | C7: 14000 | D7: =B7*C7 -> 1820000 | E7: =D7+$E$32 -> 1820000 | F7: =E7/B7 -> 14000 | H7: =A7 -> 돼지고기(앞다리, 전지)/불고기용 | I7: 130 | J7: 8500 | K7: =I7*J7 -> 1105000
A8: 돼지고기(앞다리, 전지)/찌개용 | B8: 0 | C8: 14000 | D8: =B8*C8 -> 0 | E8: =D8+$E$32 -> 0 | F8: =E8/B8 -> #DIV/0! | H8: =A8 -> 돼지고기(앞다리, 전지)/찌개용 | I8: 0 | J8: 8500 | K8: =I8*J8 -> 0
A9: 돼지고기(앞다리, 전지)/채썬것(세절) | B9: 16 | C9: 14000 | D9: =B9*C9 -> 224000 | E9: =D9+$E$32 -> 224000 | F9: =E9/B9 -> 14000 | H9: =A9 -> 돼지고기(앞다리, 전지)/채썬것(세절) | I9: 16 | J9: 8500 | K9: =I9*J9 -> 136000
A10: 돼지고기(앞다리, 전지)/편육용 | B10: 0 | C10: 15877 | D10: =B10*C10 -> 0 | E10: =D10+$E$32 -> 0 | F10: =E10/B10 -> #DIV/0! | H10: =A10 -> 돼지고기(앞다리, 전지)/편육용 | I10: 0 | J10: 8200 | K10: =I10*J10 -> 0
A11: 돼지등뼈 | B11: 43 | C11: =J11*2 -> 7600 | D11: =B11*C11 -> 326800 | E11: =D11+$E$32 -> 326800 | F11: =E11/B11 -> 7600 | H11: =A11 -> 돼지등뼈 | I11: 43 | J11: 3800 | K11: =I11*J11 -> 163400
A12: 돼지잡뼈/냉동 | B12: 48 | C12: =J12*2 -> 3600 | D12: =B12*C12 -> 172800 | E12: =D12+$E$32 -> 172800 | F12: =E12/B12 -> 3600 | H12: =A12 -> 돼지잡뼈/냉동 | I12: 48 | J12: 1800 | K12: =I12*J12 -> 86400
A13: 돼지족발 | B13: 10 | C13: =J13*2 -> 11000 | D13: =B13*C13 -> 110000 | E13: =D13+$E$32 -> 110000 | F13: =E13/B13 -> 11000 | H13: =A13 -> 돼지족발 | I13: 10 | J13: 5500 | K13: =I13*J13 -> 55000
A14: 한우(양지)/국용 | B14: 23 | C14: 41000 | D14: =B14*C14 -> 943000 | E14: =D14+$E$32 -> 943000 | F14: =E14/B14 -> 41000 | H14: =A14 -> 한우(양지)/국용 | I14: 23 | J14: 28000 | K14: =I14*J14 -> 644000
A15: 한우(우둔)/다진것 | B15: 0 | C15: 41000 | D15: =B15*C15 -> 0 | E15: =D15+$E$32 -> 0 | F15: =E15/B15 -> #DIV/0! | H15: =A15 -> 한우(우둔)/다진것 | I15: 0 | J15: 28000 | K15: =I15*J15 -> 0
A16: 한우(우둔)/장조림용 | B16: 44 | C16: 41000 | D16: =B16*C16 -> 1804000 | E16: =D16+$E$32 -> 1804000 | F16: =E16/B16 -> 41000 | H16: =A16 -> 한우(우둔)/장조림용 | I16: 44 | J16: 28000 | K16: =I16*J16 -> 1232000
D17: =B17*C17 -> 0 | E17: =D17+$E$32 -> 0 | F17: =E17/B17 -> #DIV/0! | H17: =A17 -> 0 | I17: =B17 -> 0 | K17: =I17*J17 -> 0
D18: =B18*C18 -> 0 | E18: =D18+$E$32 -> 0 | F18: =E18/B18 -> #DIV/0! | H18: =A18 -> 0 | I18: =B18 -> 0 | K18: =I18*J18 -> 0
D19: =B19*C19 -> 0 | E19: =D19+$E$32 -> 0 | F19: =E19/B19 -> #DIV/0! | H19: =A19 -> 0 | I19: =B19 -> 0 | K19: =I19*J19 -> 0
D20: =B20*C20 -> 0 | E20: =D20+$E$32 -> 0 | F20: =E20/B20 -> #DIV/0! | H20: =A20 -> 0 | I20: =B20 -> 0 | K20: =I20*J20 -> 0
H21: =A21 -> 0 | I21: =B21 -> 0 | K21: =I21*J21 -> 0
H22: =A22 -> 0 | I22: =B22 -> 0 | K22: =I22*J22 -> 0
H23: =A23 -> 0 | I23: =B23 -> 0 | K23: =I23*J23 -> 0
H24: =A24 -> 0 | I24: =B24 -> 0 | K24: =I24*J24 -> 0
H25: =A25 -> 0 | I25: =B25 -> 0 | K25: =I25*J25 -> 0
H26: =A26 -> 0 | I26: =B26 -> 0 | K26: =I26*J26 -> 0
H27: =A27 -> 0 | I27: =B27 -> 0 | K27: =I27*J27 -> 0
H28: =A28 -> 0 | I28: =B28 -> 0 | K28: =I28*J28 -> 0
H29: =A29 -> 0 | I29: =B29 -> 0 | K29: =I29*J29 -> 0
H30: =A30 -> 0 | I30: =B30 -> 0 | K30: =I30*J30 -> 0
H31: =B32 -> 8358600 | K31: =SUM(K2:K30) -> 5345800
A32: 계약금액 | B32: 8358600 | D32: =SUM(D2:D31) -> 8358600 | E32: =B32-D32 -> 0 | I32: 8 | J32: 25000 | K32: =I32*J32 -> 200000
A33: 신정초 | B33: =B2 -> 15 | C33: =$E$32/B33 -> 0 | E33: 차액 | K33: =K31+K32 -> 5545800
B34: =B3 -> 0 | C34: =$E$32/B34 -> #DIV/0! | K34: =H31-K33 -> 2812800
B35: =B4 -> 58 | C35: =$E$32/B35 -> 0 | K35: =K34/H31 -> 0.33651568
B36: =B5 -> 70 | C36: =$E$32/B36 -> 0
B37: =B6 -> 0
B38: =B7 -> 130 | G38: 3110800
B39: =B8 -> 0
B40: =B9 -> 16
...
